Workbook

Sheet Resumo 2
A2: ITEM | B2: DESCRIÇÃO DO MATERIAL | C2: UNIDADE | D2: QUANTIDADE (COM PERDAS) | E2: PREÇO UNITÁRIO | F2: TOTAL
A3: 1
A4: 1.1 | B4: Tijolo | C4: unid. | D4: 6175 | F4: =E4*D4 -> 0
A5: 1.2 | B5: Cimento | C5: saco 50 kg | D5: 198
A6: 1.3 | B6: Areia fina | C6: m³ | D6: 35
A7: 1.4 | B7: Areia grossa | C7: m³ | D7: 2.2
A8: 1.5 | B8: Brita | C8: m³ | D8: 15.5
A9: 1.6 | B9: Aço CA 60 ø5,0 mm | C9: kg | D9: 64
A10: 1.7 | B10: Aço CA 50 ø8,0 mm | C10: kg | D10: 276
A11: 1.8 | B11: Aço CA 50 ø10,0 mm | C11: kg | D11: 498
A12: 1.9 | B12: Laje pré-moldada piso | C12: m² | D12: 53.7
A13: 1.10 | B13: Laje pré-moldada forro | C13: m² | D13: 58.5
A15: =A3+1 -> 2 | B15: COBERTURA
A16: 2.1 | B16: Telha de concreto 42 X 33,4 cm | C16: unid. | D16: 950
A17: 2.2 | B17: Cumeeira | C17: unid. | D17: 68
A18: 2.3 | B18: Tesoura elementos 2 3/8" x 4 3/4" (60 mm x 120 mm) | C18: m | D18: 23
A19: 2.4 | B19: Tesoura elementos 2 3/8" x 6 3/8" (60 mm x 160 mm) | C19: m | D19: 79
A20: 2.5 | B20: Terça 2 3/8" x 4 3/4" (60 mm x 120 mm) | C20: m | D20: 86
A21: 2.6 | B21: Caibro 2" x 2 3/4" (50 mm x 70 mm) | C21: m | D21: 192
A22: 2.7 | B22: Ripa 1" x 2" (25 mm x 50 mm) | C22: m | D22: 283
A23: 2.8 | B23: Telha de fibrocimento 6 mm | C23: unid. | D23: 12
A24: 2.9 | B24: Manta térmica | C24: m² | D24: 12.8
A25: 2.10 | B25: Manta acústica | C25: m² | D25: 12.8
A26: 2.11 | B26: Esrutura metálica 1* | C26: unid. | D26: 3
A27: 2.12 | B27: Esrutura metálica 2** | C27: unid. | D27: 1
... A30: 2.15 | B30: Rufo | C30: m | D30: 3.5
B31: OBSERVAÇÕES
B32: *Treliça metálica apoiada em parede com 2,10 m de comprimeto e 0,42 m de altura
B33: **Meia treliça metálica apoiada em parede com 0,85 m de comprimeto e 0,34 m de altura
A35: =A15+1 -> 3 | B35: ACABAMENTO
A36: 3.1 | B36: Piso tipo 1* (incl. rodapé) | C36: m² | D36: 21.2
A37: 3.2 | B37: Piso tipo 2** | C37: m² | D37: 32.2
A38: 3.3 | B38: Piso tipo 3*** (incl. rodapé) | C38: m² | D38: 78.4
A39: 3.4 | B39: Piso tipo 4**** (incl. rodapé) | C39: m² | D39: 18
A40: 3.5 | B40: Azulejo para cozinha | C40: m² | D40: 53.5
A41: 3.6 | B41: Azulejo para lavabo | C41: m² | D41: 13.7
A42: 3.7 | B42: Divisória em dry wall com abertura para porta de 80cm | C42: m² | D42: 8.4
A43: 3.8 | B43: Gesso teto***** | C43: m² | D43: 9.95
A44: 3.9 | B44: Selador acrílico | C44: lata 18L | D44: 4
A45: 3.10 | B45: Selador acrílico | C45: lata 3,6L | D45: 3
...

Sheet Resumo 1
A2: Descrição do material | B2: Unidade | D2: com 10% de perda | E2: com 15% de perda
A3: Tijolo | B3: unid. | C3: =ROUNDUP(Alvenaria!J4,0) -> 5614 | D3: =ROUND(C3*1.1,0) -> 6175 | F3: 6175
A4: Cimento | B4: saco 50 kg | C4: =ROUNDUP((Alvenaria!J11+Alvenaria!J15+Alvenaria!J19+Piso!C5+Piso!C10+Estrutural!C19)/50,0) -> 180 | D4: =ROUND(C4*1.1,0) -> 198 | F4: 198
A5: Areia fina | B5: m³ | C5: =ROUNDUP((Alvenaria!J16+Alvenaria!J21+Piso!C7+Piso!C11+Estrutural!C20),1) -> 31.7 | D5: =ROUND(C5*1.1,1) -> 34.9 | F5: 35
A6: Areia grossa | B6: m³ | C6: =ROUNDUP(Alvenaria!J12,1) -> 2 | D6: =ROUND(C6*1.1,1) -> 2.2 | F6: 2.2
A7: Brita | B7: m³ | C7: =Piso!C2+Piso!C6+Estrutural!C21 -> 13.861876 | D7: =C7*1.1 -> 15.248064 | F7: 15.5
A8: Aço CA 60 ø5,0 mm | B8: kg | C8: =Estrutural!C37 -> 58.13654 | D8: =C8*1.1 -> 63.950194 | F8: 64
A9: Aço CA 50 ø8,0 mm | B9: kg | C9: =Estrutural!D37 -> 250.8645 | D9: =C9*1.1 -> 275.95095 | F9: 276
A10: Aço CA 50 ø10,0 mm | B10: kg | C10: =Estrutural!E37 -> 451.94633 | D10: =C10*1.1 -> 497.14096 | F10: 498
A11: Laje pré-moldada piso | B11: m² | C11: 53.7 | F11: 53.7
A12: Laje pré-moldada forro | B12: m² | C12: 58.43 | F12: 58.5
A14: COBERTURA
A15: Telha de concreto 42 X 33,4 cm | B15: unid. | C15: =' Cobertura'!C3 -> 863.13365 | D15: =C15*1.1 -> 949.44701 | F15: 950
A16: Cumeeira | B16: unid. | C16: =' Cobertura'!C5 -> 61.198811 | D16: =C16*1.1 -> 67.318692 | F16: 68
A17: Tesoura elementos 2 3/8" x 4 3/4" (60 mm x 120 mm) | B17: m | C17: =' Cobertura'!C6 -> 20.68 | D17: =C17*1.1 -> 22.748 | F17: 23
A18: Tesoura elementos 2 3/8" x 6 3/8" (60 mm x 160 mm) | B18: m | C18: =' Cobertura'!C7 -> 71.17 | D18: =C18*1.1 -> 78.287 | F18: 79
A19: Terça 2 3/8" x 4 3/4" (60 mm x 120 mm) | B19: m | C19: =' Cobertura'!C8 -> 78.16 | D19: =C19*1.1 -> 85.976 | F19: 86
A20: Caibro 2" x 2 3/4" (50 mm x 70 mm) | B20: m | C20: =' Cobertura'!C9 -> 174.333 | D20: =C20*1.1 -> 191.7663 | F20: 192
A21: Ripa 1" x 2" (25 mm x 50 mm) | B21: m | C21: =' Cobertura'!C10 -> 257.28022 | D21: =C21*1.1 -> 283.00824 | F21: 283
A22: Telha de fibrocimento 6 mm | B22: unid. | C22: =' Cobertura'!C14 -> 10.471274 | D22: =C22*1.1 -> 11.518401 | F22: 12
A23: Manta térmica | B23: m² | C23: =' Cobertura'!C13 -> 10.664992 | D23: =C23*1.1 -> 11.731492 | F23: 12.8
A24: Manta acústica | B24: m² | C24: =' Cobertura'!C13 -> 10.664992 | D24: =C24*1.1 -> 11.731492 | F24: 12.8
A25: Esrutura metálica 1* | B25: unid. | C25: 3 | F25: 3
A26: Esrutura metálica 2** | B26: unid. | C26: 1 | F26: 1
A27: Calha | B27: m | C27: =' Cobertura'!C16 -> 21.855 | D27: =C27*1.1 -> 24.0405 | F27: 24.5
A28: Condutor | B28: m | C28: =' Cobertura'!C17 -> 38.5 | D28: =C28*1.1 -> 42.35 | F28: 43
A29: Rufo | B29: m | C29: =' Cobertura'!C18 -> 3.16638 | D29: =C29*1.1 -> 3.483018 | F29: 3.5
A31: *Treliça metálica apoiada em parede com 2,10 m de comprimeto e 0,42 m de altura
A32: **Meia treliça metálica apoiada em parede com 0,85 m de comprimeto e 0,34 m de altura
A34: ACABAMENTO
A35: Piso tipo 1* (incl. rodapé) | B35: m² | C35: =17.46+((17.7-1-2.2-0.8)*0.07) -> 18.419 | E35: =C35*1.15 -> 21.18185 | F35: 21.2
A36: Piso tipo 2** | B36: m² | C36: =Piso!C16 -> 28.01 | E36: =Piso!E16 -> 32.2115 | F36: 32.2
A37: Piso tipo 3*** (incl. rodapé) | B37: m² | C37: =Piso!C17 -> 68.1723 | E37: =Piso!E17 -> 78.398145 | F37: 78.4
A38: Piso tipo 4**** (incl. rodapé) | B38: m² | C38: =Piso!C18 -> 15.661 | E38: =Piso!E18 -> 18.01015 | F38: 18
A39: Azulejo para cozinha | B39: m² | C39: =Piso!C19 -> 46.3 | E39: =Piso!E19 -> 53.245 | F39: 53.5
A40: Azulejo para lavabo | B40: m² | C40: =Piso!C20 -> 11.84 | E40: =Piso!E20 -> 13.616 | F40: 13.7
A41: Divisória em dry wall com abertura para porta de 80cm | B41: m² | C41: =Piso!C21 -> 8.4 | F41: 8.4
A42: Gesso teto***** | B42: m² | C42: 9.95 | F42: 9.95
A43: Selador acrílico | B43: lata 18L | C43: =Alvenaria!J32 -> 4.1386833 | D43: =C43*1.1 -> 4.5525517 | F43: 4
A44: Selador acrílico | B44: lata 3,6L | F44: 3
...

Sheet Resumo detalhado
A2: Descrição do material | B2: Unidade | D2: com 10% de perda | E2: com 15% de perda
A3: Tijolo | B3: unid. | C3: =ROUNDUP(Alvenaria!J4,0) -> 5614 | D3: =ROUND(C3*1.1,0) -> 6175
A4: Cimento | B4: saco 50 kg | C4: =ROUNDUP((Alvenaria!J11+Alvenaria!J15+Alvenaria!J19+Piso!C5+Piso!C10+Estrutural!C19)/50,0) -> 180 | D4: =ROUND(C4*1.1,0) -> 198
A5: Areia fina | B5: m³ | C5: =ROUNDUP((Alvenaria!J16+Alvenaria!J21+Piso!C7+Piso!C11+Estrutural!C20),1) -> 31.7 | D5: =ROUND(C5*1.1,1) -> 34.9
A6: Areia grossa | B6: m³ | C6: =ROUNDUP(Alvenaria!J12,1) -> 2 | D6: =ROUND(C6*1.1,1) -> 2.2
A7: Brita | B7: m³ | C7: =Piso!C2+Piso!C6+Estrutural!C21 -> 13.861876 | D7: =C7*1.1 -> 15.248064
A8: Aço CA 60 ø5,0 mm | B8: kg | C8: =Estrutural!C37 -> 58.13654 | D8: =C8*1.1 -> 63.950194
A9: Aço CA 50 ø8,0 mm | B9: kg | C9: =Estrutural!D37 -> 250.8645 | D9: =C9*1.1 -> 275.95095
A10: Aço CA 50 ø10,0 mm | B10: kg | C10: =Estrutural!E37 -> 451.94633 | D10: =C10*1.1 -> 497.14096
A11: Laje pré-moldada piso | B11: m² | C11: 53.7
A12: Laje pré-moldada forro | B12: m² | C12: 58.43
A14: COBERTURA
A15: Telha de concreto 42 X 33,4 cm | B15: unid. | C15: =' Cobertura'!C3 -> 863.13365 | D15: =C15*1.1 -> 949.44701
A16: Cumeeira | B16: unid. | C16: =' Cobertura'!C5 -> 61.198811 | D16: =C16*1.1 -> 67.318692
A17: Tesoura elementos 2 3/8" x 4 3/4" (60 mm x 120 mm) | B17: m | C17: =' Cobertura'!C6 -> 20.68 | D17: =C17*1.1 -> 22.748
A18: Tesoura elementos 2 3/8" x 6 3/8" (60 mm x 160 mm) | B18: m | C18: =' Cobertura'!C7 -> 71.17 | D18: =C18*1.1 -> 78.287
A19: Terça 2 3/8" x 4 3/4" (60 mm x 120 mm) | B19: m | C19: =' Cobertura'!C8 -> 78.16 | D19: =C19*1.1 -> 85.976
A20: Caibro 2" x 2 3/4" (50 mm x 70 mm) | B20: m | C20: =' Cobertura'!C9 -> 174.333 | D20: =C20*1.1 -> 191.7663
A21: Ripa 1" x 2" (25 mm x 50 mm) | B21: m | C21: =' Cobertura'!C10 -> 257.28022 | D21: =C21*1.1 -> 283.00824
A22: Telha de fibrocimento 6 mm | B22: unid. | C22: =' Cobertura'!C14 -> 10.471274 | D22: =C22*1.1 -> 11.518401
A23: Manta térmica | B23: m² | C23: =' Cobertura'!C13 -> 10.664992 | D23: =C23*1.1 -> 11.731492
A24: Manta acústica | B24: m² | C24: =' Cobertura'!C13 -> 10.664992 | D24: =C24*1.1 -> 11.731492
A25: Esrutura metálica 1* | B25: unid. | C25: 3
A26: Esrutura metálica 2** | B26: unid. | C26: 1
A27: Calha | B27: m | C27: =' Cobertura'!C16 -> 21.855 | D27: =C27*1.1 -> 24.0405
A28: Condutor | B28: m | C28: =' Cobertura'!C17 -> 38.5 | D28: =C28*1.1 -> 42.35
A29: Rufo | B29: m | C29: =' Cobertura'!C18 -> 3.16638 | D29: =C29*1.1 -> 3.483018
A31: *Treliça metálica apoiada em parede com 2,10 m de comprimeto e 0,42 m de altura
A32: **Meia treliça metálica apoiada em parede com 0,85 m de comprimeto e 0,34 m de altura
A34: ACABAMENTO
A35: Piso tipo 1* (incl. rodapé) | B35: m² | C35: =17.46+((17.7-1-2.2-0.8)*0.07) -> 18.419 | E35: =C35*1.15 -> 21.18185
A36: Piso tipo 2** | B36: m² | C36: =Piso!C16 -> 28.01 | E36: =Piso!E16 -> 32.2115
A37: Piso tipo 3*** (incl. rodapé) | B37: m² | C37: =Piso!C17 -> 68.1723 | E37: =Piso!E17 -> 78.398145
A38: Piso tipo 4**** (incl. rodapé) | B38: m² | C38: =Piso!C18 -> 15.661 | E38: =Piso!E18 -> 18.01015
A39: Azulejo para cozinha | B39: m² | C39: =Piso!C19 -> 46.3 | E39: =Piso!E19 -> 53.245
A40: Azulejo para lavabo | B40: m² | C40: =Piso!C20 -> 11.84 | E40: =Piso!E20 -> 13.616
A41: Divisória em dry wall com abertura para porta de 80cm | B41: m² | C41: =Piso!C21 -> 8.4
A42: Gesso teto***** | B42: m² | C42: 9.95
A43: Selador acrílico | B43: lata 18L | C43: =Alvenaria!J32 -> 4.1386833
A44: Massa corrida acrílica | B44: lata 18L | C44: =Alvenaria!J33 -> 6.75684
...

Sheet  Cobertura
G1: Tabela - Dimensões convencionais dos elementos de uma tesoura para vãos menores que 10 metros
A2: Área cobertura telha de concreto | B2: m² | C2: =77.06*1.077 -> 82.99362 | G2: Peça da tesoura | H2: vão em metros
A3: Telha de concreto | B3: unid. | C3: =10.4*C2 -> 863.13365 | H3: 6 m | I3: 8 m | J3: 10 m
A4: Cumeeira | B4: m | C4: =4.2426*3+5.91+1.37+2.86*2+1.2 -> 26.9278 | G4: Linha (banzo inferior) | H4: 6 x 12 | I4: 6 x 16 | J4: 6 x 16
A5: Cumeeira | B5: unid. | C5: =2.2727*C4 -> 61.198811 | G5: Perna (banzo superior) | H5: 6 x16 | I5: 6 x16 | J5: 6 x16
A6: Tesoura elementos 2 3/8" x 4 3/4" (60 mm x 120 mm) | B6: m | C6: =1.22*4+0.65*4+1.65*2*4 -> 20.68 | D6: * Montantes, diagonais | G6: Mão francesa | H6: 6 x 12 | I6: 6 x 12 | J6: 6 x 12
A7: Tesoura elementos 2 3/8" x 6 3/8" (60 mm x 160 mm) | B7: m | C7: =12.67*4+3.28*3+2.13*5 -> 71.17 | D7: *Banzo | G7: Pendural (montante central) | H7: 6 x 12 | I7: 6 x 12 | J7: 6 x 12
A8: Terça 2 3/8" x 4 3/4" (60 mm x 120 mm) | B8: m | C8: =11.91+8.86+5.81+7.86+7.5+5.81+6.1+3.5+7.2+4.2+4.05+2.03+1.11*3 -> 78.16 | G8: Tirante (montantes) | H8: 6 x 12 | I8: 6 x 12 | J8: 6 x 12
A9: Caibro 2" x 2 3/4" (50 mm x 70 mm) | B9: m | C9: =(11.9/0.5*3.3*2)+(2.13*8.1) -> 174.333
A10: Ripa 1" x 2" (25 mm x 50 mm) | B10: m | C10: =C2*3.1 -> 257.28022
A13: Telha fibrocimento | B13: m² | C13: =9.9025*1.077 -> 10.664992
A14: Telha fibrocimento | B14: unid. | C14: =C13/(0.97*1.05) -> 10.471274
A16: Calha | B16: m | C16: =11-1.895+2.45+0.8+4.25+5.25 -> 21.855
A17: Condutor | B17: m | C17: =5.5*7 -> 38.5
A18: Rufo | B18: m | C18: =2.94*1.077 -> 3.16638

Sheet Piso
A2: Lastro de brita 2 | B2: m³ | C2: =57.53*0.03 -> 1.7259
A4: Lastro de concreto não estrutural 1:4:6 | B4: m³ | C4: =57.53*0.05 -> 2.8765
A5: Cimento | B5: kg | C5: =(222*C4) -> 638.583
A6: Brita 02 | B6: m³ | C6: =0.952*C4 -> 2.738428
A7: Areia | B7: m³ | C7: =0.7703*C4 -> 2.215768
A9: Contrapiso (1:4) | B9: m³ | C9: =(57.53+17.41+22.31+7.51+6.82+7.5)*0.02 -> 2.3816
A10: Cimento | B10: kg | C10: =C9*342.1 -> 814.74536
A11: Areia | B11: m³ | C11: =C9*1.294 -> 3.0817904
D13: + 10% de perda | E13: +15% de perda
A14: Acabamento
A15: Piso tipo 1* (incl. rodapé) | B15: m² | C15: =17.46+((17.7-1-2.2-0.8)*0.07) -> 18.419 | E15: =C15*1.15 -> 21.18185
A16: Piso tipo 2** | B16: m² | C16: =4.2+22.31+1.5 -> 28.01 | E16: =C16*1.15 -> 32.2115
A17: Piso tipo 3** (incl. rodapé) | B17: m² | C17: =6.82+7.51+19.57+31.2+((8.55+0.95+15.45+10.49+8.45)*0.07) -> 68.1723 | E17: =C17*1.15 -> 78.398145
A18: Piso tipo 4**** (incl. rodapé) | B18: m² | C18: =14.94+(10.3*0.07) -> 15.661 | E18: =C18*1.15 -> 18.01015
A19: Azulejo cozinha | B19: m² | C19: =(20.1*2.8)-(2*2.1)-(0.8*2.1)-(2)-(2.1) -> 46.3 | E19: =C19*1.15 -> 53.245
A20: Azulejo lavabo | B20: m² | C20: =(5*2.8)-(0.8*2.1)-(0.8*0.6) -> 11.84 | E20: =C20*1.15 -> 13.616
A21: Divisória em dry wall com abertura para porta de 80cm | B21: m² | C21: =3.6*2.8-0.8*2.1 -> 8.4
A22: Selador
A23: Massa corrida
A24: Tinta PVA ou acrilíca (pintura interna)
A25: Tinta texturizada (pintura externa)
A28: * Copa
A29: ** Cozinha, lavabo e escada
A30: *** Jardim de inverno, área de serviço, sacada e área da churrasqueira
A31: *** Calçada abaixo da sacada

Sheet Alvenaria
A2: ALVENARIA SUPERIOR | I2: UNID.
A3: Parede | B3: Comprimento | C3: Altura | D3: Abertura | E3: Área bruta | F3: Área líquida | H3: Área alvenaria | I3: m² | J3: =F15+F25 -> 168.42
A4: 1 | B4: 7.7 | C4: 2.8 | D4: =2+(2.1*2) -> 6.2 | E4: =B4*C4 -> 21.56 | F4: =E4-D4 -> 15.36 | H4: Tijolo 9 x 14 x 19 | I4: UNID. | J4: =J3*33.33 -> 5613.4386
A5: 2 | B5: 2.15 | C5: 2.8 | E5: =B5*C5 -> 6.02 | F5: =E5-D5 -> 6.02 | H5: Tijolo 9 x 14 x 19 (+10%) | I5: UNID. | J5: =J4*1.1 -> 6174.7825
A6: 3 | B6: 6.55 | C6: 2.8 | D6: =2.1*2+2.8 -> 7 | E6: =B6*C6 -> 18.34 | F6: =E6-D6 -> 11.34
A7: 4 | B7: 1 | C7: 2.8 | E7: =B7*C7 -> 2.8 | F7: =E7-D7 -> 2.8 | H7: Teto | I7: m² | J7: =35.59+22.31+7.51+17.41 -> 82.82
A8: 5 | B8: 3.6 | C8: 2.8 | D8: =2*2.1 -> 4.2 | E8: =B8*C8 -> 10.08 | F8: =E8-D8 -> 5.88
A9: 6 | B9: 3.5 | C9: 2.8 | E9: =B9*C9 -> 9.8 | F9: =E9-D9 -> 9.8
A10: 7 | B10: 5.55 | C10: 2.8 | E10: =B10*C10 -> 15.54 | F10: =E10-D10 -> 15.54 | H10: Argamassa de assentamento 1:6 (cimento e areia grossa) | I10: m³ | J10: =0.01*J3 -> 1.6842
A11: 8 | B11: 2.9 | C11: 2.8 | E11: =B11*C11 -> 8.12 | F11: =E11-D11 -> 8.12 | H11: Cimento (270 kg para 1m³) | I11: kg | J11: =J10*230 -> 387.366
A12: 9 | B12: 3.95 | C12: 2.8 | D12: =0.55*2.8*2 -> 3.08 | E12: =B12*C12 -> 11.06 | F12: =E12-D12 -> 7.98 | H12: Areia grossa | I12: m³ | J12: =J10*1.14 -> 1.919988
A13: 10 | B13: 6.55 | C13: 2.8 | D13: 2 | E13: =B13*C13 -> 18.34 | F13: =E13-D13 -> 16.34
A14: 11 | B14: 1.5 | C14: 2.8 | E14: =B14*C14 -> 4.2 | F14: =E14-D14 -> 4.2 | H14: Chapisco alvenaria e teto (1:4) | I14: m³ | J14: =(J3+J7)*2*0.005 -> 2.5124
F15: =SUM(F4:F14) -> 103.38 | H15: Cimento (342,1 kg para 1m³) | I15: kg | J15: =J14*342.1 -> 859.49204
H16: Areia fina | I16: m³ | J16: =J14*1.294 -> 3.2510456
A17: ALVENARIA INFERIOR
A18: Parede | B18: Comprimento | C18: Altura | D18: Abertura | E18: Área bruta | F18: Área líquida | H18: Massa única alvenaria e teto (1:2:9) | I18: m³ | J18: =(J3+J7)*2*0.02 -> 10.0496
A19: 12 | B19: 10 | C19: 2.4 | E19: =B19*C19 -> 24 | F19: =E19-D19 -> 24 | H19: Cimento (181,3 kg para 1m³) | I19: kg | J19: =J18*181.3 -> 1821.9925
A20: 13 | B20: 1 | C20: 2.4 | E20: =B20*C20 -> 2.4 | F20: =E20-D20 -> 2.4 | H20: Cal (181,3 kg para 1m³) | I20: m³ | J20: =J18*181.3 -> 1821.9925
A21: 14 | B21: 5.55 | C21: 2.4 | E21: =B21*C21 -> 13.32 | F21: =E21-D21 -> 13.32 | H21: Areia fina | I21: m³ | J21: =J18*1.496 -> 15.034202
A22: 15 | B22: 5.55 | C22: 2.4 | E22: =B22*C22 -> 13.32 | F22: =E22-D22 -> 13.32
A23: 16 | B23: 3.5 | C23: 2.4 | E23: =B23*C23 -> 8.4 | F23: =E23-D23 -> 8.4
A24: 17 | B24: 1.5 | C24: 2.4 | E24: =B24*C24 -> 3.6 | F24: =E24-D24 -> 3.6
F25: =SUM(F19:F24) -> 65.04
A28: PINTURA INTERNA | H28: Pintura interna 3 demão | I28: 18L | J28: =F35/110 -> 2.1429273
A29: Parede | B29: Comprimento | C29: Altura | D29: Abertura | E29: Área bruta | F29: Área líquida | H29: Pintura teto 2 demão | I29: 3,6L | J29: =F37/25 -> 4.0848
A30: Suíte | B30: 18.01 | C30: 2.8 | D30: =(0.8*2.1)+(0.7*2.1)+(2.1*2) -> 7.35 | E30: =B30*C30 -> 50.428 | F30: =E30-D30 -> 43.078 | H30: Pintura texturizada | I30: 26kg | J30: =F44/14 -> 11.342857
A31: Copa | B31: 17.7 | C31: 2.8 | D31: =2*2.1+2+0.8*2.1 -> 7.88 | E31: =B31*C31 -> 49.56 | F31: =E31-D31 -> 41.68 | H31: Impermeabilização com manta liquida 2 demão | I31: 14kg | J31: =F48/7.5 -> 5.016
A32: Área de serviço | B32: 11.29 | C32: 2.8 | D32: =2.1*0.8+2 -> 3.68 | E32: =B32*C32 -> 31.612 | F32: =E32-D32 -> 27.932 | H32: Selador acrílico 1 demão | I32: 18L | J32: =(F35+F37+F44)/120 -> 4.1386833
A33: Escada | B33: =(1.45+3.65)*5.4+3.5*2.8 -> 37.34 | C33: 2.8 | E33: =B33*C33 -> 104.552 | F33: =E33-D33 -> 104.552 | H33: Massa corrida | I33: 27kg | J33: =(F35+F37)/50 -> 6.75684
A34: Dry wall | B34: 7.2 | C34: 2.8 | D34: =0.8*2.1 -> 1.68 | E34: =B34*C34 -> 20.16 | F34: =E34-D34 -> 18.48
F35: =SUM(F30:F34) -> 235.722
A37: Teto | F37: =17.46+7.53+22.31+19.57+31.18+4.07 -> 102.12
A40: PINTURA EXTERNA
A41: Parede | B41: Comprimento | C41: Altura | D41: Abertura | E41: Área bruta | F41: Área líquida
A42: externa | B42: =25+0.2*4*3 -> 27.4 | C42: 5.4 | D42: =2*2.1*3+2*2+0.8*2.1*2 -> 19.96 | E42: =B42*C42 -> 147.96 | F42: =E42-D42 -> 128
A43: Jardim de inverno | B43: 11 | C43: 2.8 | E43: =B43*C43 -> 30.8 | F43: =E43-D43 -> 30.8
F44: =SUM(F42:F43) -> 158.8
A46: IMPERMEABILIZAÇÃO
A47: Parede | B47: Comprimento | C47: Altura | D47: Abertura | E47: Área bruta | F47: Área líquida
...

Sheet Estrutural
A1: CONCRETO
A2: Estacas | F2: Pilares | K2: Viga subsolo
A3: Quantidade | B3: Comprimento | C3: Área | D3: Volume Concreto | F3: Quantidade | G3: Comprimento | H3: Área | I3: Volume Concreto | K3: Quantidade | L3: Comprimento | M3: Área | N3: Volume Concreto
A4: 16 | B4: 4 | C4: =0.125*0.125*3.14 -> 0.0490625 | D4: =C4*B4*A4 -> 3.14 | F4: 3 | G4: 5.4 | H4: =0.2*0.2 -> 0.04 | I4: =H4*G4*F4 -> 0.648 | L4: =10.3*3+5.15+7.2+3.65+2.3*3 -> 53.8 | M4: =0.14*0.3 -> 0.042 | N4: =M4*L4 -> 2.2596
F5: 7 | G5: 5.4 | H5: =0.14*0.3 -> 0.042 | I5: =H5*G5*F5 -> 1.5876
F6: 3 | G6: 5.4 | H6: =0.14*0.14 -> 0.0196 | I6: =H6*G6*F6 -> 0.31752
A7: Bloco | I7: =SUM(I4:I6) -> 2.55312 | K7: Viga cobertura
A8: Quantidade | B8: Altura | C8: Área | D8: Volume Concreto | K8: Quantidade | L8: Comprimento | M8: Área | N8: Volume Concreto
A9: 10 | B9: =0.3 -> 0.3 | C9: =0.5*0.5 -> 0.25 | D9: =C9*B9*A9 -> 0.75 | F9: Forma pilar | L9: =10.3*3+5.15+7.2+2.3 -> 45.55 | M9: =0.14*0.3 -> 0.042 | N9: =M9*L9 -> 1.9131
A10: 3 | B10: 0.3 | C10: =1.25*0.5 -> 0.625 | D10: =C10*B10*A10 -> 0.5625 | F10: Quantidade | G10: Comprimento | H10: Perimetro | I10: Área (M²)
D11: =SUM(D9:D10) -> 1.3125 | F11: 3 | G11: 5.4 | H11: =0.2*4 -> 0.8 | I11: =H11*G11*F11 -> 12.96
F12: 7 | G12: 5.4 | H12: =0.14*2+0.3*2 -> 0.88 | I12: =H12*G12*F12 -> 33.264
A13: Baldrame | F13: 3 | G13: 5.4 | H13: =0.14*4 -> 0.56 | I13: =H13*G13*F13 -> 9.072
A14: Quantidade | B14: Comprimento | C14: Área | D14: Volume Concreto | I14: =SUM(I11:I13) -> 55.296
B15: =10.3*2+5.15+7.2+2.3*2+3.65 -> 41.2 | C15: =0.14*0.3 -> 0.042 | D15: =C15*B15 -> 1.7304
A18: Concreto | B18: m³ | C18: =D4+D11+D15+I7+N4+N9 -> 12.90872
A19: Cimento | B19: kg | C19: =C18*344 -> 4440.5997
A20: Areia | B20: m³ | C20: =0.622*C18 -> 8.0292238
A21: Brita | B21: m³ | C21: =0.728*C18 -> 9.3975482
A25: AÇO
B26: Quantidade | C26: 5 mm | D26: 8 mm | E26: 10 mm
A27: Estaca | B27: 16 | C27: =2*3.14*0.125*10*16 -> 125.6 | E27: =4*2.5*B27 -> 160
A28: Bloco 1 | D28: =((0.2*2+0.44*2+0.1)*3*10) -> 41.4 | E28: =((0.44*4+0.1)*3*10) -> 55.8
A29: Bloco 2 | D29: =((0.2*2+0.44*2+0.1)*7*10) -> 96.6 | E29: =(0.44*2+1.19*2+0.1)*3*3 -> 30.24
A30: Pilar 1 | B30: 3 | C30: =(0.17*4+0.05)*27*B30 -> 59.13 | E30: =4*G4*B30 -> 64.8
A31: Pilar 2 | B31: 7 | C31: =(0.27*2+0.11*2+0.05)*27*B31 -> 153.09 | D31: =4*B31*G5 -> 151.2
A32: Pilar 3 | B32: 3 | C32: =(0.11*4+0.05)*27*B32 -> 39.69 | D32: =4*F6*G6 -> 64.8
A33: Viga baldrame | D33: =2*B15 -> 82.4 | E33: =3*B15 -> 123.6
A34: Viga subsolo | D34: =L4*2 -> 107.6 | E34: =L4*3 -> 161.4
A35: Viga cobertura | D35: =L9*2 -> 91.1 | E35: =L9*3 -> 136.65
B36: TOTAL (m) | C36: =SUM(C27:C35) -> 377.51 | D36: =SUM(D27:D35) -> 635.1 | E36: =SUM(E27:E35) -> 732.49
B37: TOTAL (kg) | C37: =C36*0.154 -> 58.13654 | D37: =D36*0.395 -> 250.8645 | E37: =E36*0.617 -> 451.94633
